Workbook

Sheet Auto Refresh Execution Log
A1: Refresh Time | B1: Sheet | C1: Operation | D1: Status | E1: User
A2: 46062.331 | B2: Price Multipliers | C2: Report Id: 00OVO000003z2O92AI | D2: Success | E2: jad.hajjar@cloudkitchens.com
A3: 46062.331 | B3: SF Churn Data | C3: Report Id: 00O6T000006Y5DiUAK | D3: Success | E3: jad.hajjar@cloudkitchens.com
A4: 46062.331 | B4: Area Data | C4: Report Id: 00O6T000006Y0l6UAC | D4: Success | E4: jad.hajjar@cloudkitchens.com
A5: 46062.331 | B5: All no status kitchens | C5: Report Id: 00O6T000006DPigUAG | D5: Success | E5: jad.hajjar@cloudkitchens.com
A6: 46062.331 | B6: Sellable No Status | C6: Report Id: 00O6T000006DXT0UAO | D6: Success | E6: jad.hajjar@cloudkitchens.com
A7: 46062.331 | B7: SF Kitchen Data | C7: Report Id: 00O6T000006Y0l6UAC | D7: Success | E7: jad.hajjar@cloudkitchens.com
A8: 46062.165 | B8: Price Multipliers | C8: Report Id: 00OVO000003z2O92AI | D8: Success | E8: jad.hajjar@cloudkitchens.com
A9: 46062.165 | B9: SF Churn Data | C9: Report Id: 00O6T000006Y5DiUAK | D9: Success | E9: jad.hajjar@cloudkitchens.com
A10: 46062.165 | B10: Area Data | C10: Report Id: 00O6T000006Y0l6UAC | D10: Success | E10: jad.hajjar@cloudkitchens.com
A11: 46062.165 | B11: All no status kitchens | C11: Report Id: 00O6T000006DPigUAG | D11: Success | E11: jad.hajjar@cloudkitchens.com
A12: 46062.165 | B12: Sellable No Status | C12: Report Id: 00O6T000006DXT0UAO | D12: Success | E12: jad.hajjar@cloudkitchens.com
A13: 46062.165 | B13: SF Kitchen Data | C13: Report Id: 00O6T000006Y0l6UAC | D13: Success | E13: jad.hajjar@cloudkitchens.com
... A101: 46059.665 | B101: All no status kitchens | C101: Report Id: 00O6T000006DPigUAG | D101: Success | E101: jad.hajjar@cloudkitchens.com

Sheet SF Kitchen Data
A1: Account Name | B1: Type | C1: Category | D1: Kitchen Number ID 18 | E1: Kitchen Number Name | F1: Status | G1: Kitchen Size (Sq. Meters) | H1: Hood Size | I1: Floor Price | J1: List Price | K1: Activation Fee | L1: Opportunity ID 18 | M1: Opportunity Name | N1: Opportunity Owner: Full Name | O1: Floor | P1: County | Q1: Churn Date
A2: SA - RUH - Aqiq | B2: CPU | C2: X | D2: a1LVO000003qvTV2AY | E2: K22 (CPU) - SA - RUH - Aqiq | H2: NA | I2: 1666.66 | J2: 2250 | O2: GF | P2: North West | Q2: =IFERROR(VLOOKUP(E2,'SF Churn Data'!E:R,14,0),"")
A3: SA - RUH - Arid (2) | B3: Hot | C3: Cold | D3: a1LVO000004E6w52AC | E3: K04 (Cold) - SA - RUH - Arid (2) | G3: 10.62 | H3: Cold | I3: 5100 | J3: 6150 | O3: GF | P3: North | Q3: =IFERROR(VLOOKUP(E3,'SF Churn Data'!E:R,14,0),"")
A4: SA - RUH - Narjis | B4: Cold | C4: COLD | D4: a1L6T00000iJA28UAG | E4: K01 (Cold) - SA - RUH - Narjis | G4: 9.12 | H4: NA | I4: 3551 | J4: 4100 | K4: 4350 | O4: GF | P4: North | Q4: =IFERROR(VLOOKUP(E4,'SF Churn Data'!E:R,14,0),"")
A5: SA - RUH - Arid (2) | B5: Hot | C5: C | D5: a1LVO000004E7H32AK | E5: K17 (Hot) - SA - RUH - Arid (2) | G5: 15.03 | H5: 2.4m | I5: 6400 | J5: 7700 | O5: 1st | P5: North | Q5: =IFERROR(VLOOKUP(E5,'SF Churn Data'!E:R,14,0),"")
A6: SA - RUH - Mursalat | B6: Hot Kitchen | C6: C | D6: a1LVO000002yMFp2AM | E6: K06 (Hot) - SA - MUR | G6: 15.04 | H6: 2.4m Hood | I6: 6430 | J6: 6450 | O6: 1st | P6: Center | Q6: =IFERROR(VLOOKUP(E6,'SF Churn Data'!E:R,14,0),"")
A7: SA - RUH - Mursalat | B7: Hot Kitchen | C7: D | D7: a1LVO000002yMHR2A2 | E7: K07 (Hot) - SA - MUR | G7: 17.06 | H7: 3.0m Hood | I7: 6861 | J7: 6900 | O7: 1st | P7: Center | Q7: =IFERROR(VLOOKUP(E7,'SF Churn Data'!E:R,14,0),"")
A8: SA - RUH - Mursalat | B8: Hot Kitchen | C8: C | D8: a1LVO000002yMJ32AM | E8: K08 (Hot) - SA - MUR | G8: 15.04 | H8: 2.4m Hood | I8: 6430 | J8: 6450 | O8: 1st | P8: Center | Q8: =IFERROR(VLOOKUP(E8,'SF Churn Data'!E:R,14,0),"")
A9: SA - RUH - Mursalat | B9: Hot Kitchen | C9: C | D9: a1LVO000002yMAz2AM | E9: K03 (Hot) - SA - MUR | G9: 15.15 | H9: 2.4m Hood | I9: 6430 | J9: 6450 | O9: 1st | P9: Center | Q9: =IFERROR(VLOOKUP(E9,'SF Churn Data'!E:R,14,0),"")
A10: SA - RUH - Mursalat | B10: Hot Kitchen | C10: D | D10: a1LVO000002yMCb2AM | E10: K04 (Hot) - SA - MUR | G10: 17.06 | H10: 3.0m Hood | I10: 6861 | J10: 6900 | O10: 1st | P10: Center | Q10: =IFERROR(VLOOKUP(E10,'SF Churn Data'!E:R,14,0),"")
A11: SA - RUH - Mursalat | B11: Hot Kitchen | C11: C | D11: a1LVO000002yMED2A2 | E11: K05 (Hot) - SA - MUR | G11: 15.04 | H11: 2.4m Hood | I11: 6430 | J11: 6450 | O11: 1st | P11: Center | Q11: =IFERROR(VLOOKUP(E11,'SF Churn Data'!E:R,14,0),"")
A12: SA - RUH - Mursalat | B12: Hot Kitchen | C12: E | D12: a1LVO000002yM9N2AU | E12: K02 (Hot) - SA - MUR | G12: 19.04 | H12: 3.0m Hood | I12: 7300 | J12: 7300 | O12: 1st | P12: Center | Q12: =IFERROR(VLOOKUP(E12,'SF Churn Data'!E:R,14,0),"")
A13: SA - RUH - Mursalat | B13: Hot Kitchen | C13: E | D13: a1LVO000002yM7l2AE | E13: K01 (Hot) - SA - MUR | G13: 19.04 | H13: 3.0m Hood | I13: 7300 | J13: 7300 | O13: 1st | P13: Center | Q13: =IFERROR(VLOOKUP(E13,'SF Churn Data'!E:R,14,0),"")
A14: SA - RUH - Mursalat | B14: Hot Kitchen | C14: C | D14: a1LVO000002yMfd2AE | E14: K23 (Hot) - SA - MUR | G14: 15.03 | H14: 2.4m Hood | I14: 6430 | J14: 6450 | O14: 2nd | P14: Center | Q14: =IFERROR(VLOOKUP(E14,'SF Churn Data'!E:R,14,0),"")
A15: SA - RUH - Mursalat | B15: Hot Kitchen | C15: E | D15: a1LVO000002yMhF2AU | E15: K22 (Hot) - SA - MUR | G15: 19.15 | H15: 3.0m Hood | I15: 7300 | J15: 7300 | O15: 2nd | P15: Center | Q15: =IFERROR(VLOOKUP(E15,'SF Churn Data'!E:R,14,0),"")
A16: SA - RUH - Mursalat | B16: Hot Kitchen | C16: C | D16: a1LVO000002yMcP2AU | E16: K21 (Hot) - SA - MUR | G16: 15.03 | H16: 2.4m Hood | I16: 6430 | J16: 6450 | O16: 2nd | P16: Center | Q16: =IFERROR(VLOOKUP(E16,'SF Churn Data'!E:R,14,0),"")
... A28: SA - RUH - Mursalat | B28: Hot Kitchen | C28: C | D28: a1LVO000002yMMH2A2 | E28: K10 (Hot) - SA - MUR | G28: 15.04 | H28: 2.4m Hood | I28: 6430 | J28: 6450 | O28: 1st | P28: Center | Q28: =IFERROR(VLOOKUP(E28,'SF Churn Data'!E:R,14,0),"")
A29: SA - RUH - Malga (1) | B29: Hot | C29: A | D29: a1L5G000004NKhtUAG | E29: K16 (Hot) - SA - RUH - Malga 1 | G29: 11.9 | H29: 2.0m | I29: 5148 | J29: 7250 | K29: 6200 | O29: 1st Floor | P29: North West | Q29: =IFERROR(VLOOKUP(E29,'SF Churn Data'!E:R,14,0),"")
A30: SA - RUH - Malga (1) | B30: Hot | C30: C | D30: a1L5G000004NKhvUAG | E30: K18 (Hot) - SA - RUH - Malga 1 | G30: 16.9 | H30: 3.0m | I30: 6437 | J30: 9050 | K30: 7750 | O30: 1st Floor | P30: North West | Q30: =IFERROR(VLOOKUP(E30,'SF Churn Data'!E:R,14,0),"")
A31: SA - RUH - Malga (1) | B31: Hot | C31: C | D31: a1L5G000004NKhwUAG | E31: K19 (Hot) - SA - RUH - Malga 1 | G31: 16 | H31: 2.4m | I31: 6008 | J31: 8450 | K31: 7300 | O31: 1st Floor | P31: North West | Q31: =IFERROR(VLOOKUP(E31,'SF Churn Data'!E:R,14,0),"")
A32: SA - RUH - Malga (1) | B32: Hot | C32: A | D32: a1L5G000004NKhlUAG | E32: K08 (Hot) - SA - RUH - Malga 1 | G32: 11.3 | H32: 2.0m | I32: 5148 | J32: 7250 | K32: 6200 | O32: GF | P32: North West | Q32: =IFERROR(VLOOKUP(E32,'SF Churn Data'!E:R,14,0),"")
A33: SA - QSM - Al Bishr | B33: Hot | C33: E | D33: a1L6T00000d2MvuUAE | E33: K13 (Hot) - SA - RUH - QSM | F33: Churning | G33: 21.06 | H33: 3.0m | I33: 3229 | J33: 2750 | K33: 3900 | L33: 006VO00000TRgP3YAL | M33: Samoli Ep | N33: Riyad Ali | O33: 2nd | Q33: =IFERROR(VLOOKUP(E33,'SF Churn Data'!E:R,14,0),"") -> 46078
A34: SA - AHS - Hofuf | B34: Hot | C34: B | D34: a1L6T00000iJLZdUAO | E34: K06 (Hot)- KSA - AHS- Hofuf | F34: Churning | G34: 14.78 | H34: 2.4m Hood | I34: 2975.44 | J34: 2400 | K34: 3500 | L34: 006VO00000dcowbYAA | M34: Nukhba al Wasal hofouf | N34: Riyad Ali | O34: GF | Q34: =IFERROR(VLOOKUP(E34,'SF Churn Data'!E:R,14,0),"") -> 46065
A35: SA - RUH - Khaleej | B35: Hot | C35: A | D35: a1L5G000004NSiDUAW | E35: K26 (Hot) - SA - RUH - Khaleej | F35: Churning | G35: 11.97 | H35: 2.0m | I35: 2482 | J35: 3600 | K35: 3000 | L35: 006VO00000eOAaHYAW | M35: Al Normani Khaleej | N35: Shiraz Ali | O35: 1st | P35: East | Q35: =IFERROR(VLOOKUP(E35,'SF Churn Data'!E:R,14,0),"") -> 46082
A36: SA - RUH - Olaya | B36: Hot | C36: C | D36: a1L5G000004Tzj8UAC | E36: K16 (Hot) - SA - RUH - Olaya | F36: Churning | G36: 16 | H36: 2.4m | I36: 8592 | J36: 9500 | K36: 10350 | O36: 1st | P36: Center | Q36: =IFERROR(VLOOKUP(E36,'SF Churn Data'!E:R,14,0),"") -> 46082
A37: SA - RUH - Wadi | B37: Hot | C37: D | D37: a1L5G000004TzoXUAS | E37: K07 (Hot) - SA - RUH - Wadi | F37: Churning | G37: 18.1 | H37: 2.4m | I37: 7096 | J37: 7100 | K37: 8550 | O37: G | P37: North | Q37: =IFERROR(VLOOKUP(E37,'SF Churn Data'!E:R,14,0),"") -> 46081
A38: SA - RUH - Wadi | B38: Hot | C38: E | D38: a1L5G000004TzpbUAC | E38: K45 (Hot) - SA - RUH - Wadi | F38: Churning | G38: 20.8 | H38: 2.4m | I38: 7514 | J38: 7550 | K38: 9100 | O38: 1st | P38: North | Q38: =IFERROR(VLOOKUP(E38,'SF Churn Data'!E:R,14,0),"") -> 46082
A39: SA - RUH - Qurtoba | B39: Hot | C39: C | D39: a1L5G000004TzsPUAS | E39: K10 (Hot) SA - RUH - Qurtoba | F39: Churning | G39: 16 | H39: 2.4m | I39: 4799 | J39: 6750 | K39: 5800 | O39: G | P39: North East | Q39: =IFERROR(VLOOKUP(E39,'SF Churn Data'!E:R,14,0),"") -> 46068
A40: SA - RUH - Dahrat Laban | B40: Hot | C40: B | D40: a1L5G000004TzmgUAC | E40: K16 (Hot) - SA - RUH - Dahrat Laban | F40: Churning | G40: 14.54 | H40: 2.4m | I40: 4666 | J40: 4700 | K40: 5650 | O40: Mez | P40: South West | Q40: =IFERROR(VLOOKUP(E40,'SF Churn Data'!E:R,14,0),"") -> 46082
A41: SA - RUH - Wadi | B41: Hot | C41: D | D41: a1L5G000004TzoIUAS | E41: K04 (Hot) - SA - RUH - Wadi | F41: Churning | G41: 18.1 | H41: 2.4m | I41: 7096 | J41: 7100 | K41: 8550 | O41: G | P41: North | Q41: =IFERROR(VLOOKUP(E41,'SF Churn Data'!E:R,14,0),"") -> 46082
A42: SA - DMM - Zuhur | B42: Hot | C42: G | D42: a1L5G000004NecqUAC | E42: K22 (Hot) - SA - DMM - Zuhur | F42: Churning | G42: 24.71 | H42: 4.0m | I42: 4750 | J42: 5700 | K42: 5700 | O42: 1st Floor | Q42: =IFERROR(VLOOKUP(E42,'SF Churn Data'!E:R,14,0),"") -> 46081
A43: SA - RUH - Khaleej | B43: Hot | C43: D | D43: a1L5G000004NSi3UAG | E43: K16 (Hot) - SA - RUH - Khaleej | F43: Churning | G43: 19.55 | H43: 3.0m | I43: 3944 | J43: 5750 | K43: 4750 | O43: 1st | P43: East | Q43: =IFERROR(VLOOKUP(E43,'SF Churn Data'!E:R,14,0),"") -> 46082
A44: SA - KBR - Aqrabiya | B44: Hot | C44: C | D44: a1L5G000004NYIEUA4 | E44: K16 (Hot) - SA - KBR - Aqrabiya | F44: Churning | G44: 15.43 | H44: 2.4m | I44: 4250 | J44: 4900 | K44: 5100 | O44: 1st Floor | Q44: =IFERROR(VLOOKUP(E44,'SF Churn Data'!E:R,14,0),"") -> 46081
A45: SA - KBR - Aqrabiya | B45: Hot | C45: C | D45: a1L5G000004NYIDUA4 | E45: K15 (Hot) - SA - KBR - Aqrabiya | F45: Churning | G45: 15.67 | H45: 2.4m | I45: 4250 | J45: 4900 | K45: 5100 | O45: 1st Floor | Q45: =IFERROR(VLOOKUP(E45,'SF Churn Data'!E:R,14,0),"") -> 46081
A46: SA - KBR - Aqrabiya | B46: Hot | C46: D | D46: a1L5G000004NYI4UAO | E46: K06 (Hot) - SA - KBR - Aqrabiya | F46: Churning | G46: 18.31 | H46: 3.0m | I46: 4990 | J46: 5750 | K46: 6000 | O46: GF | Q46: =IFERROR(VLOOKUP(E46,'SF Churn Data'!E:R,14,0),"") -> 46127
A47: SA - RUH - Qurtoba | B47: Hot | C47: C | D47: a1L5G000004TzstUAC | E47: K18 (Hot) SA - RUH - Qurtoba | F47: Churning | G47: 16 | H47: 2.4m | I47: 4799 | J47: 6750 | K47: 5800 | O47: G | P47: North East | Q47: =IFERROR(VLOOKUP(E47,'SF Churn Data'!E:R,14,0),"") -> 46082
A48: SA - RUH - Qurtoba | B48: Hot | C48: F | D48: a1L5G000004TzsoUAC | E48: K16 (Hot) SA - RUH - Qurtoba | F48: Churning | G48: 22 | H48: 2.4m | I48: 6090 | J48: 8550 | K48: 7350 | O48: G | P48: North East | Q48: =IFERROR(VLOOKUP(E48,'SF Churn Data'!E:R,14,0),"") -> 46068
A49: SA - RUH - Qurtoba | B49: Hot | C49: F | D49: a1L5G000004TzsjUAC | E49: K15 (Hot) SA - RUH - Qurtoba | F49: Churning | G49: 22 | H49: 2.4m | I49: 6090 | J49: 8550 | K49: 7350 | O49: G | P49: North East | Q49: =IFERROR(VLOOKUP(E49,'SF Churn Data'!E:R,14,0),"") -> 46130
A50: SA - RUH - Qurtoba | B50: Hot | C50: D | D50: a1L5G000004TztDUAS | E50: K22 (Hot) SA - RUH - Qurtoba | F50: Churning | G50: 17 | H50: 2.4m | I50: 5731 | J50: 8050 | K50: 6900 | O50: G | P50: North East | Q50: =IFERROR(VLOOKUP(E50,'SF Churn Data'!E:R,14,0),"") -> 46082
A51: SA - RUH - Qurtoba | B51: Cold | C51: Cold | D51: a1L5G000004TzuuUAC | E51: K02 (Cold) SA - RUH - Qurtoba | F51: Churning | G51: 11 | H51: Cold | I51: 3580 | J51: 5050 | K51: 4350 | O51: G | P51: North East | Q51: =IFERROR(VLOOKUP(E51,'SF Churn Data'!E:R,14,0),"") -> 46082
...

Sheet Sellable No Status
A1: Type | B1: Category | C1: Kitchen Number ID 18 | D1: Kitchen Number Name | E1: Status | F1: Kitchen Size (Sq. Meters) | G1: Hood Size | H1: Floor Price | I1: MSRP | J1: Activation Fee | K1: Opportunity ID 18 | L1: Opportunity Name | M1: Opportunity Owner: Full Name | N1: Floor | O1: Electric Load (kW) | P1: Gas Load (kW)
A2: CloudRetail | B2: B | C2: a1L5G000004NedAUAS | D2: K23 (Hot) - SA - DMM - Zuhur | F2: 14.28 | G2: 2.4m | H2: 3086 | I2: 3200 | J2: 3750 | N2: 1st Floor | O2: 40 Amps | P2: 37 mBar
A3: CPU | B3: X | C3: a1LVO000003qvTV2AY | D3: K22 (CPU) - SA - RUH - Aqiq | G3: NA | H3: 1666.66 | I3: 1666.66 | N3: GF
A4: Cold | B4: Cold | C4: a1L5G000004NsYYUA0 | D4: K09 (Cold) - SA - RUH - Aqiq (Deprecated) | F4: 11.16 | G4: Cold | H4: 2885 | I4: 3000 | J4: 3500 | N4: 1st | O4: 30 Amps | P4: N/A
A5: CloudRetail | B5: Cold | C5: a1L6T00000jr3ncUAA | D5: K16 (Cold) - SA - RUH - Jarir | F5: 10.11 | G5: N/A | H5: 1998.75 | I5: 2100 | J5: 2400 | N5: 1st Floor | O5: 30 Amps | P5: N/A
A6: Cold | B6: COLD | C6: a1L6T00000iJA28UAG | D6: K01 (Cold) - SA - RUH - Narjis | F6: 9.12 | G6: NA | H6: 3551 | I6: 3700 | J6: 4350 | N6: GF | O6: 30 Amps | P6: N/A
A7: Cold | B7: Cold | C7: a1L5G000004TzupUAC | D7: K01 (Cold) SA - RUH - Qurtoba (Deprecated) | F7: 11 | G7: Cold | H7: 3580 | I7: 3600 | J7: 4350 | N7: G | O7: 30 Amps | P7: N/A
A8: Cold | B8: Cold | C8: a1L6T00000jqkpGUAQ | D8: K16 (Cold) - SA - RUH - Salam (Deprecated) | F8: 8.11 | G8: Cold | H8: 2600 | I8: 2500 | J8: 3000 | N8: 1st | O8: 30 Amps | P8: N/A
A9: CloudRetail | B9: B | C9: a1L6T00000jqkp8UAA | D9: K02 (Hot) - SA - RUH - Salam | F9: 12.33 | G9: 2.4m | H9: 4650 | I9: 4800 | J9: 5400 | N9: GF | O9: 40 Amps | P9: 37 mBar
A10: Cold | B10: Cold | C10: a1L6T00000iJBYPUA4 | D10: K05 (Cold) - SA - RUH - Sulimaniyah (Deprecated) | F10: 12.8 | G10: NA | H10: 3100 | I10: 3200 | J10: 3750 | N10: 1st | O10: 30 Amps | P10: N/A

Sheet All no status kitchens
A1: Type | B1: Category | C1: Kitchen Number ID 18 | D1: Kitchen Number Name | E1: Status | F1: Kitchen Size (Sq. Meters) | G1: Hood Size | H1: Floor Price | I1: MSRP | J1: Activation Fee | K1: Opportunity ID 18 | L1: Opportunity Name | M1: Opportunity Owner: Full Name | N1: Floor | O1: Electric Load (kW) | P1: Gas Load (kW)
A2: CPU | B2: X | C2: a1LVO000003qvTV2AY | D2: K22 (CPU) - SA - RUH - Aqiq | G2: NA | H2: 1666.66 | I2: 1666.66 | N2: GF
A3: CloudRetail | B3: B | C3: a1L5G000004NedAUAS | D3: K23 (Hot) - SA - DMM - Zuhur | F3: 14.28 | G3: 2.4m | H3: 3086 | I3: 3200 | J3: 3750 | N3: 1st Floor | O3: 40 Amps | P3: 37 mBar
A4: Hot | B4: Cold | C4: a1LVO000004E6w52AC | D4: K04 (Cold) - SA - RUH - Arid (2) | F4: 10.62 | G4: Cold | H4: 5100 | N4: GF
A5: Cold | B5: COLD | C5: a1L6T00000iJA28UAG | D5: K01 (Cold) - SA - RUH - Narjis | F5: 9.12 | G5: NA | H5: 3551 | I5: 3700 | J5: 4350 | N5: GF | O5: 30 Amps | P5: N/A
A6: Hot | B6: C | C6: a1LVO000004E7H32AK | D6: K17 (Hot) - SA - RUH - Arid (2) | F6: 15.03 | G6: 2.4m | H6: 6400 | N6: 1st
A7: Hot Kitchen | B7: C | C7: a1LVO000002yMFp2AM | D7: K06 (Hot) - SA - MUR | F7: 15.04 | G7: 2.4m Hood | H7: 6430 | N7: 1st
A8: Hot Kitchen | B8: D | C8: a1LVO000002yMHR2A2 | D8: K07 (Hot) - SA - MUR | F8: 17.06 | G8: 3.0m Hood | H8: 6861 | N8: 1st
A9: Hot Kitchen | B9: C | C9: a1LVO000002yMJ32AM | D9: K08 (Hot) - SA - MUR | F9: 15.04 | G9: 2.4m Hood | H9: 6430 | N9: 1st
A10: Hot Kitchen | B10: C | C10: a1LVO000002yMAz2AM | D10: K03 (Hot) - SA - MUR | F10: 15.15 | G10: 2.4m Hood | H10: 6430 | N10: 1st
A11: Hot Kitchen | B11: D | C11: a1LVO000002yMCb2AM | D11: K04 (Hot) - SA - MUR | F11: 17.06 | G11: 3.0m Hood | H11: 6861 | N11: 1st
A12: Hot Kitchen | B12: C | C12: a1LVO000002yMED2A2 | D12: K05 (Hot) - SA - MUR | F12: 15.04 | G12: 2.4m Hood | H12: 6430 | N12: 1st
A13: Hot Kitchen | B13: E | C13: a1LVO000002yM9N2AU | D13: K02 (Hot) - SA - MUR | F13: 19.04 | G13: 3.0m Hood | H13: 7300 | N13: 1st
A14: Hot Kitchen | B14: E | C14: a1LVO000002yM7l2AE | D14: K01 (Hot) - SA - MUR | F14: 19.04 | G14: 3.0m Hood | H14: 7300 | N14: 1st
A15: Hot Kitchen | B15: C | C15: a1LVO000002yMfd2AE | D15: K23 (Hot) - SA - MUR | F15: 15.03 | G15: 2.4m Hood | H15: 6430 | N15: 2nd
A16: Hot Kitchen | B16: E | C16: a1LVO000002yMhF2AU | D16: K22 (Hot) - SA - MUR | F16: 19.15 | G16: 3.0m Hood | H16: 7300 | N16: 2nd
A17: Hot Kitchen | B17: C | C17: a1LVO000002yMcP2AU | D17: K21 (Hot) - SA - MUR | F17: 15.03 | G17: 2.4m Hood | H17: 6430 | N17: 2nd
A18: CloudRetail | B18: B | C18: a1L6T00000jqkp8UAA | D18: K02 (Hot) - SA - RUH - Salam | F18: 12.33 | G18: 2.4m | H18: 4650 | I18: 4800 | J18: 5400 | N18: GF | O18: 40 Amps | P18: 37 mBar
A19: Hot Kitchen | B19: E | C19: a1LVO000002yMe12AE | D19: K20 (Hot) - SA - MUR | F19: 19.04 | G19: 3.0m Hood | H19: 7300 | N19: 2nd
A20: Hot Kitchen | B20: E | C20: a1LVO000002yMan2AE | D20: K18 (Hot) - SA - MUR | F20: 19.04 | G20: 3.0m Hood | H20: 7300 | N20: 2nd
A21: Hot Kitchen | B21: D | C21: a1LVO000002yMVx2AM | D21: K16 (Hot) - SA - MUR | F21: 17.06 | G21: 3.0m Hood | H21: 6861 | N21: 1st
A22: Hot Kitchen | B22: C | C22: a1LVO000002yMXZ2A2 | D22: K17 (Hot) - SA - MUR | F22: 15.03 | G22: 2.4m Hood | H22: 6430 | N22: 2nd
A23: Hot Kitchen | B23: C | C23: a1LVO000002yMZB2A2 | D23: K19 (Hot) - SA - MUR | F23: 15.03 | G23: 2.4m Hood | H23: 6430 | N23: 2nd
A24: Hot Kitchen | B24: C | C24: a1LVO000002yMSj2AM | D24: K14 (Hot) - SA - MUR | F24: 15.04 | G24: 2.4m Hood | H24: 6430 | N24: 1st
A25: Hot Kitchen | B25: D | C25: a1LVO000002yMUL2A2 | D25: K15 (Hot) - SA - MUR | F25: 17.06 | G25: 3.0m Hood | H25: 6861 | N25: 1st
A26: Hot Kitchen | B26: D | C26: a1LVO000002yMNt2AM | D26: K11 (Hot) - SA - MUR | F26: 17.06 | G26: 3.0m Hood | H26: 6861 | N26: 1st
A27: Hot Kitchen | B27: C | C27: a1LVO000002yMPV2A2 | D27: K12 (Hot) - SA - MUR | F27: 15.04 | G27: 2.4m Hood | H27: 6430 | N27: 1st
A28: Hot Kitchen | B28: D | C28: a1LVO000002yMR72AM | D28: K13 (Hot) - SA - MUR | F28: 17.06 | G28: 3.0m Hood | H28: 6861 | N28: 1st
A29: Hot Kitchen | B29: D | C29: a1LVO000002yMKf2AM | D29: K09 (Hot) - SA - MUR | F29: 17.06 | G29: 3.0m Hood | H29: 6861 | N29: 1st
A30: Hot Kitchen | B30: C | C30: a1LVO000002yMMH2A2 | D30: K10 (Hot) - SA - MUR | F30: 15.04 | G30: 2.4m Hood | H30: 6430 | N30: 1st
A31: CloudRetail | B31: Cold | C31: a1L5G000004O0LgUAK | D31: K07 (Cold) - SA - RUH - Sweidi | F31: 6.2 | G31: Cold | H31: 3100 | I31: 3200 | J31: 3600 | N31: Mez | O31: 30 Amps | P31: N/A
A32: Hot | B32: A | C32: a1L5G000004NKhtUAG | D32: K16 (Hot) - SA - RUH - Malga 1 | F32: 11.9 | G32: 2.0m | H32: 5148 | I32: 5350 | J32: 6200 | N32: 1st Floor | O32: 40 Amps | P32: 37 mBar
A33: Hot | B33: C | C33: a1L5G000004NKhvUAG | D33: K18 (Hot) - SA - RUH - Malga 1 | F33: 16.9 | G33: 3.0m | H33: 6437 | I33: 6450 | J33: 7750 | N33: 1st Floor | O33: 40 Amps | P33: 37 mBar
A34: Hot | B34: C | C34: a1L5G000004NKhwUAG | D34: K19 (Hot) - SA - RUH - Malga 1 | F34: 16 | G34: 2.4m | H34: 6008 | I34: 6200 | J34: 7300 | N34: 1st Floor | O34: 40 Amps | P34: 37 mBar
A35: Hot | B35: A | C35: a1L5G000004NKhlUAG | D35: K08 (Hot) - SA - RUH - Malga 1 | F35: 11.3 | G35: 2.0m | H35: 5148 | I35: 5350 | J35: 6200 | N35: GF | O35: 40 Amps | P35: 37 mBar
A36: CloudRetail | B36: Cold | C36: a1L6T00000jr3ncUAA | D36: K16 (Cold) - SA - RUH - Jarir | F36: 10.11 | G36: N/A | H36: 1998.75 | I36: 2100 | J36: 2400 | N36: 1st Floor | O36: 30 Amps | P36: N/A

Sheet LF Comp
A1: Account Name | B1: Type | C1: Category | D1: Kitchen Number ID 18 | E1: Kitchen Number Name | F1: Status | G1: Kitchen Size (Sq. Meters) | H1: Hood Size | I1: Floor Price | J1: Sell Price | K1: Activation Fee | L1: Opportunity ID 18 | M1: Opportunity Name | N1: Opportunity Owner: Full Name | O1: Floor | P1: County | Q1: Monthly License Fee
A2: SA - JED - Rehab | B2: Hot | C2: F | D2: a1L6T00000iJ1DzUAK | E2: K20 (Hot) - SA - JED - Rehab | G2: 23.02 | H2: 4.0m | I2: 5750 | J2: 5750 | K2: 7400 | L2: 0066T00001AsymIQAR | M2: Delivery Hero - K20 (Hot) - SA - JED - Rehab | N2: Jad Hajjar | O2: 1st | Q2: 5569
A3: SA - JED - Rehab | B3: Hot | C3: D | D3: a1L6T00000iJ1DyUAK | E3: K19 (Hot) - SA - JED - Rehab | G3: 18.63 | H3: 3.0m | I3: 4800 | J3: 4800 | K3: 6100 | L3: 0066T00001AsymmQAB | M3: Delivery Hero - K19 (Hot) - SA - JED - Rehab | N3: Jad Hajjar | O3: 1st | Q3: 4643
A4: SA - RUH - Aqiq | B4: CPU | C4: X | D4: a1LVO000003qvTV2AY | E4: K22 (CPU) - SA - RUH - Aqiq | H4: NA | I4: 1666.66 | J4: 2250 | O4: GF | P4: North West
A5: SA - JED - Safa | B5: Hot | C5: Cold | D5: a1L5G000004NcycUAC | E5: K31 (Hot) - SA - SAF | G5: 14.37 | H5: N/A | J5: 0 | K5: 2450 | O5: 2nd
A6: SA - JED - Safa | B6: Hot | C6: D | D6: a1L5G000004NcybUAC | E6: K30 (Hot) - SA - SAF | G6: 18 | H6: 3.0m | J6: 0 | K6: 6250 | O6: 2nd
A7: SA - JED - Safa | B7: Cold | C7: Cold | D7: a1L5G000004NcyeUAC | E7: K33 (Cold) - SA - SAF | G7: 12.62 | H7: N/A | J7: 0 | K7: 2450 | O7: 2nd
A8: SA - JED - Safa | B8: Cold | C8: Cold | D8: a1L5G000004NcydUAC | E8: K32 (Cold) - SA - SAF | G8: 12.6 | H8: N/A | J8: 0 | K8: 2450 | O8: 2nd
A9: SA - JED - Safa | B9: Hot | C9: B | D9: a1L5G000004NcygUAC | E9: K35 (Hot) - SA - SAF | G9: 13.51 | H9: 2.4m | J9: 0 | K9: 5300 | O9: 2nd
A10: SA - JED - Safa | B10: Cold | C10: B | D10: a1L5G000004NcyfUAC | E10: K34 (Cold) - SA - SAF | G10: 13.49 | H10: 2.4m | J10: 0 | K10: 5300 | O10: 2nd
A11: SA - JED - Safa | B11: Hot | C11: D | D11: a1L5G000004NcyhUAC | E11: K36 (Hot) - SA - SAF | G11: 19.49 | H11: 3.0m | J11: 0 | K11: 6250 | O11: 2nd
A12: SA - RUH - Arid (2) | B12: Hot | C12: D | D12: a1LVO000004E6sr2AC | E12: K02 (Hot) - SA - RUH - Arid (2) | G12: 17.05 | H12: 3.0m | I12: 6800 | J12: 8200 | O12: GF | P12: North
A13: SA - RUH - Arid (2) | B13: Hot | C13: Cold | D13: a1LVO000004E6w52AC | E13: K04 (Cold) - SA - RUH - Arid (2) | G13: 10.62 | H13: Cold | I13: 5100 | J13: 6150 | O13: GF | P13: North
A14: SA - RUH - Arid (2) | B14: Hot | C14: C | D14: a1LVO000004E7H32AK | E14: K17 (Hot) - SA - RUH - Arid (2) | G14: 15.03 | H14: 2.4m | I14: 6400 | J14: 7700 | O14: 1st | P14: North
A15: SA - RUH - Mursalat | B15: Hot Kitchen | C15: C | D15: a1LVO000002yMFp2AM | E15: K06 (Hot) - SA - MUR | G15: 15.04 | H15: 2.4m Hood | I15: 6430 | J15: 6450 | O15: 1st | P15: Center
A16: SA - RUH - Mursalat | B16: Hot Kitchen | C16: D | D16: a1LVO000002yMHR2A2 | E16: K07 (Hot) - SA - MUR | G16: 17.06 | H16: 3.0m Hood | I16: 6861 | J16: 6900 | O16: 1st | P16: Center
A17: SA - RUH - Mursalat | B17: Hot Kitchen | C17: C | D17: a1LVO000002yMJ32AM | E17: K08 (Hot) - SA - MUR | G17: 15.04 | H17: 2.4m Hood | I17: 6430 | J17: 6450 | O17: 1st | P17: Center
A18: SA - RUH - Mursalat | B18: Hot Kitchen | C18: C | D18: a1LVO000002yMAz2AM | E18: K03 (Hot) - SA - MUR | G18: 15.15 | H18: 2.4m Hood | I18: 6430 | J18: 6450 | O18: 1st | P18: Center
A19: SA - RUH - Mursalat | B19: Hot Kitchen | C19: D | D19: a1LVO000002yMCb2AM | E19: K04 (Hot) - SA - MUR | G19: 17.06 | H19: 3.0m Hood | I19: 6861 | J19: 6900 | O19: 1st | P19: Center
A20: SA - RUH - Mursalat | B20: Hot Kitchen | C20: C | D20: a1LVO000002yMED2A2 | E20: K05 (Hot) - SA - MUR | G20: 15.04 | H20: 2.4m Hood | I20: 6430 | J20: 6450 | O20: 1st | P20: Center
A21: SA - RUH - Mursalat | B21: Hot Kitchen | C21: E | D21: a1LVO000002yM9N2AU | E21: K02 (Hot) - SA - MUR | G21: 19.04 | H21: 3.0m Hood | I21: 7300 | J21: 7300 | O21: 1st | P21: Center
A22: SA - RUH - Mursalat | B22: Hot Kitchen | C22: E | D22: a1LVO000002yM7l2AE | E22: K01 (Hot) - SA - MUR | G22: 19.04 | H22: 3.0m Hood | I22: 7300 | J22: 7300 | O22: 1st | P22: Center
A23: SA - RUH - Mursalat | B23: Hot Kitchen | C23: C | D23: a1LVO000002yMfd2AE | E23: K23 (Hot) - SA - MUR | G23: 15.03 | H23: 2.4m Hood | I23: 6430 | J23: 6450 | O23: 2nd | P23: Center
... A37: SA - RUH - Mursalat | B37: Hot Kitchen | C37: C | D37: a1LVO000002yMMH2A2 | E37: K10 (Hot) - SA - MUR | G37: 15.04 | H37: 2.4m Hood | I37: 6430 | J37: 6450 | O37: 1st | P37: Center
A38: SA - RUH - Malga (1) | B38: Hot | C38: A | D38: a1L5G000004NKhtUAG | E38: K16 (Hot) - SA - RUH - Malga 1 | G38: 11.9 | H38: 2.0m | I38: 5148 | J38: 7250 | K38: 6200 | O38: 1st Floor | P38: North West
A39: SA - RUH - Malga (1) | B39: Hot | C39: C | D39: a1L5G000004NKhvUAG | E39: K18 (Hot) - SA - RUH - Malga 1 | G39: 16.9 | H39: 3.0m | I39: 6437 | J39: 9050 | K39: 7750 | O39: 1st Floor | P39: North West
A40: SA - RUH - Malga (1) | B40: Hot | C40: C | D40: a1L5G000004NKhwUAG | E40: K19 (Hot) - SA - RUH - Malga 1 | G40: 16 | H40: 2.4m | I40: 6008 | J40: 8450 | K40: 7300 | O40: 1st Floor | P40: North West
A41: SA - RUH - Malga (1) | B41: Hot | C41: A | D41: a1L5G000004NKhlUAG | E41: K08 (Hot) - SA - RUH - Malga 1 | G41: 11.3 | H41: 2.0m | I41: 5148 | J41: 7250 | K41: 6200 | O41: GF | P41: North West
A42: SA - QSM - Al Bishr | B42: Hot | C42: E | D42: a1L6T00000d2MvuUAE | E42: K13 (Hot) - SA - RUH - QSM | F42: Churning | G42: 21.06 | H42: 3.0m | I42: 3229 | J42: 2750 | K42: 3900 | L42: 006VO00000TRgP3YAL | M42: Samoli Ep | N42: Riyad Ali | O42: 2nd | Q42: 2300
A43: SA - RUH - Khaleej | B43: Cold | C43: Cold | D43: a1L5G000004NSi2UAG | E43: K09 (Cold) - SA - RUH - Khaleej | F43: Churning | G43: 8.85 | H43: Cold | I43: 1652 | J43: 2400 | K43: 2050 | L43: 006VO00000VwQDBYA3 | M43: Al Ghalia Company - CAFÉ LILOU - KHJ | N43: Yousif Almohammedali | O43: GF | P43: East | Q43: 1900
A44: SA - RUH - Dahrat Laban | B44: Hot | C44: D | D44: a1L5G000004TzmlUAC | E44: K18 (Hot) - SA - RUH - Dahrat Laban | F44: Churning | G44: 18.75 | H44: 3.0m | I44: 5516 | J44: 5550 | K44: 6700 | L44: 006VO00000bLFupYAG | M44: Maqloba - KSA | N44: Osama Eliewa | O44: Mez | P44: South West | Q44: 6150
A45: SA - RUH - Khaleej | B45: Hot | C45: D | D45: a1L5G000004NSiAUAW | E45: K23 (Hot) - SA - RUH - Khaleej | F45: Churning | G45: 18.21 | H45: 3.0m | I45: 3944 | J45: 5750 | K45: 4750 | L45: 006VO00000biAPmYAM | M45: chicken worx | N45: Riyad Ali | O45: 1st | P45: East | Q45: 5150
A46: SA - DMM - Rawda | B46: Hot | C46: B | D46: a1L6T00000iJ1ETUA0 | E46: K21 (Hot) - SA - DMM - Rawda | F46: Churning | G46: 13.5 | H46: 2.4m | I46: 2800 | J46: 3400 | K46: 3250 | L46: 006VO00000bogI6YAI | M46: Shawayet Hasan -KSA | N46: Abdelrahman Matar | O46: 1st | Q46: 3450
A47: SA - RUH - Dahrat Laban | B47: Hot | C47: B | D47: a1L5G000004TzipUAC | E47: K17 (Hot) - SA - RUH - Dahrat Laban | F47: Churning | G47: 14.54 | H47: 2.4m | I47: 4666 | J47: 4700 | K47: 5650 | O47: Mez | P47: South West
A48: SA - RUH - Sweidi | B48: Hot | C48: D | D48: a1L5G000004TzkQUAS | E48: K10 (Hot) - SA - RUH - Sweidi | F48: Churning | G48: 17.9 | H48: 3.0m | I48: 6200 | J48: 8100 | K48: 7200 | O48: GF | P48: South West
A49: SA - RUH - Sweidi | B49: Hot | C49: D | D49: a1L5G000004TzkLUAS | E49: K09 (Hot) - SA - RUH - Sweidi | F49: Churning | G49: 17.9 | H49: 3.0m | I49: 6200 | J49: 8100 | K49: 7200 | O49: GF | P49: South West
A50: SA - RUH - Olaya | B50: Cold | C50: Cold | D50: a1L5G000004TzjhUAC | E50: K03 (Cold) - SA - RUH - Olaya | F50: Churning | G50: 7.1 | H50: Cold | I50: 4215 | J50: 4650 | K50: 5100 | O50: 1st | P50: Center
A51: SA - RUH - Wadi | B51: Hot | C51: E | D51: a1L5G000004TzpbUAC | E51: K45 (Hot) - SA - RUH - Wadi | F51: Churning | G51: 20.8 | H51: 2.4m | I51: 7514 | J51: 7550 | K51: 9100 | O51: 1st | P51: North
A52: SA - RUH - Wadi | B52: Hot | C52: D | D52: a1L5G000004TzqxUAC | E52: K40 (Hot) - SA - RUH - Wadi | F52: Churning | G52: 17.6 | H52: 2.4m | I52: 7096 | J52: 7100 | K52: 8550 | O52: 1st | P52: North
A53: SA - RUH - Qurtoba | B53: Hot | C53: F | D53: a1L5G000004TzsUUAS | E53: K12 (Hot) SA - RUH - Qurtoba | F53: Churning | G53: 22 | H53: 2.4m | I53: 6090 | J53: 8550 | K53: 7350 | O53: G | P53: North East
...

Sheet Pivot Table 10
D1: Delta
D2: =C2/B2 -> 1
D3: =C3/B3 -> 0.90332877
D4: =C4/B4 -> 0.85250868
D5: =C5/B5 -> 1
D6: =C6/B6 -> 1.1383809
D7: =C7/B7 -> 0.98121201
D8: =C8/B8 -> 1.0299711
D9: =C9/B9 -> 0.97677794
D10: =C10/B10 -> 0.99553571
D11: =C11/B11 -> 0.8198021
D12: =C12/B12 -> 0.96339601
D13: =C13/B13 -> 0.92606714
... D40: =C40/B40 -> 1.0018791

Sheet Area Data
A1: Account Name | B1: Type | C1: Category | D1: Kitchen Number ID 18 | E1: Kitchen Number Name | F1: Status | G1: Kitchen Size (Sq. Meters) | H1: Hood Size | I1: Floor Price | J1: List Price | K1: Activation Fee | L1: Opportunity ID 18 | M1: Opportunity Name | N1: Opportunity Owner: Full Name | O1: Floor | P1: County | Q1: Real-time Sold Status
A2: SA - RUH - Aqiq | B2: CPU | C2: X | D2: a1LVO000003qvTV2AY | E2: K22 (CPU) - SA - RUH - Aqiq | H2: NA | I2: 1666.66 | J2: 2250 | O2: GF | P2: North West | Q2: =SUM(COUNTIF(F2,"Occupied"),Countif(F2,"Churning"),Countif(F2,"Sold"),COUNTIFS(F2,"Vacant",M2,"<>")) -> 0
A3: SA - RUH - Arid (2) | B3: Hot | C3: Cold | D3: a1LVO000004E6w52AC | E3: K04 (Cold) - SA - RUH - Arid (2) | G3: 10.62 | H3: Cold | I3: 5100 | J3: 6150 | O3: GF | P3: North | Q3: =SUM(COUNTIF(F3,"Occupied"),Countif(F3,"Churning"),Countif(F3,"Sold"),COUNTIFS(F3,"Vacant",M3,"<>")) -> 0
A4: SA - RUH - Narjis | B4: Cold | C4: COLD | D4: a1L6T00000iJA28UAG | E4: K01 (Cold) - SA - RUH - Narjis | G4: 9.12 | H4: NA | I4: 3551 | J4: 4100 | K4: 4350 | O4: GF | P4: North | Q4: =SUM(COUNTIF(F4,"Occupied"),Countif(F4,"Churning"),Countif(F4,"Sold"),COUNTIFS(F4,"Vacant",M4,"<>")) -> 0
A5: SA - RUH - Arid (2) | B5: Hot | C5: C | D5: a1LVO000004E7H32AK | E5: K17 (Hot) - SA - RUH - Arid (2) | G5: 15.03 | H5: 2.4m | I5: 6400 | J5: 7700 | O5: 1st | P5: North | Q5: =SUM(COUNTIF(F5,"Occupied"),Countif(F5,"Churning"),Countif(F5,"Sold"),COUNTIFS(F5,"Vacant",M5,"<>")) -> 0
A6: SA - RUH - Mursalat | B6: Hot Kitchen | C6: C | D6: a1LVO000002yMFp2AM | E6: K06 (Hot) - SA - MUR | G6: 15.04 | H6: 2.4m Hood | I6: 6430 | J6: 6450 | O6: 1st | P6: Center | Q6: =SUM(COUNTIF(F6,"Occupied"),Countif(F6,"Churning"),Countif(F6,"Sold"),COUNTIFS(F6,"Vacant",M6,"<>")) -> 0
A7: SA - RUH - Mursalat | B7: Hot Kitchen | C7: D | D7: a1LVO000002yMHR2A2 | E7: K07 (Hot) - SA - MUR | G7: 17.06 | H7: 3.0m Hood | I7: 6861 | J7: 6900 | O7: 1st | P7: Center | Q7: =SUM(COUNTIF(F7,"Occupied"),Countif(F7,"Churning"),Countif(F7,"Sold"),COUNTIFS(F7,"Vacant",M7,"<>")) -> 0
A8: SA - RUH - Mursalat | B8: Hot Kitchen | C8: C | D8: a1LVO000002yMJ32AM | E8: K08 (Hot) - SA - MUR | G8: 15.04 | H8: 2.4m Hood | I8: 6430 | J8: 6450 | O8: 1st | P8: Center | Q8: =SUM(COUNTIF(F8,"Occupied"),Countif(F8,"Churning"),Countif(F8,"Sold"),COUNTIFS(F8,"Vacant",M8,"<>")) -> 0
A9: SA - RUH - Mursalat | B9: Hot Kitchen | C9: C | D9: a1LVO000002yMAz2AM | E9: K03 (Hot) - SA - MUR | G9: 15.15 | H9: 2.4m Hood | I9: 6430 | J9: 6450 | O9: 1st | P9: Center | Q9: =SUM(COUNTIF(F9,"Occupied"),Countif(F9,"Churning"),Countif(F9,"Sold"),COUNTIFS(F9,"Vacant",M9,"<>")) -> 0
A10: SA - RUH - Mursalat | B10: Hot Kitchen | C10: D | D10: a1LVO000002yMCb2AM | E10: K04 (Hot) - SA - MUR | G10: 17.06 | H10: 3.0m Hood | I10: 6861 | J10: 6900 | O10: 1st | P10: Center | Q10: =SUM(COUNTIF(F10,"Occupied"),Countif(F10,"Churning"),Countif(F10,"Sold"),COUNTIFS(F10,"Vacant",M10,"<>")) -> 0
A11: SA - RUH - Mursalat | B11: Hot Kitchen | C11: C | D11: a1LVO000002yMED2A2 | E11: K05 (Hot) - SA - MUR | G11: 15.04 | H11: 2.4m Hood | I11: 6430 | J11: 6450 | O11: 1st | P11: Center | Q11: =SUM(COUNTIF(F11,"Occupied"),Countif(F11,"Churning"),Countif(F11,"Sold"),COUNTIFS(F11,"Vacant",M11,"<>")) -> 0
A12: SA - RUH - Mursalat | B12: Hot Kitchen | C12: E | D12: a1LVO000002yM9N2AU | E12: K02 (Hot) - SA - MUR | G12: 19.04 | H12: 3.0m Hood | I12: 7300 | J12: 7300 | O12: 1st | P12: Center | Q12: =SUM(COUNTIF(F12,"Occupied"),Countif(F12,"Churning"),Countif(F12,"Sold"),COUNTIFS(F12,"Vacant",M12,"<>")) -> 0
A13: SA - RUH - Mursalat | B13: Hot Kitchen | C13: E | D13: a1LVO000002yM7l2AE | E13: K01 (Hot) - SA - MUR | G13: 19.04 | H13: 3.0m Hood | I13: 7300 | J13: 7300 | O13: 1st | P13: Center | Q13: =SUM(COUNTIF(F13,"Occupied"),Countif(F13,"Churning"),Countif(F13,"Sold"),COUNTIFS(F13,"Vacant",M13,"<>")) -> 0
A14: SA - RUH - Mursalat | B14: Hot Kitchen | C14: C | D14: a1LVO000002yMfd2AE | E14: K23 (Hot) - SA - MUR | G14: 15.03 | H14: 2.4m Hood | I14: 6430 | J14: 6450 | O14: 2nd | P14: Center | Q14: =SUM(COUNTIF(F14,"Occupied"),Countif(F14,"Churning"),Countif(F14,"Sold"),COUNTIFS(F14,"Vacant",M14,"<>")) -> 0
A15: SA - RUH - Mursalat | B15: Hot Kitchen | C15: E | D15: a1LVO000002yMhF2AU | E15: K22 (Hot) - SA - MUR | G15: 19.15 | H15: 3.0m Hood | I15: 7300 | J15: 7300 | O15: 2nd | P15: Center | Q15: =SUM(COUNTIF(F15,"Occupied"),Countif(F15,"Churning"),Countif(F15,"Sold"),COUNTIFS(F15,"Vacant",M15,"<>")) -> 0
A16: SA - RUH - Mursalat | B16: Hot Kitchen | C16: C | D16: a1LVO000002yMcP2AU | E16: K21 (Hot) - SA - MUR | G16: 15.03 | H16: 2.4m Hood | I16: 6430 | J16: 6450 | O16: 2nd | P16: Center | Q16: =SUM(COUNTIF(F16,"Occupied"),Countif(F16,"Churning"),Countif(F16,"Sold"),COUNTIFS(F16,"Vacant",M16,"<>")) -> 0
... A28: SA - RUH - Mursalat | B28: Hot Kitchen | C28: C | D28: a1LVO000002yMMH2A2 | E28: K10 (Hot) - SA - MUR | G28: 15.04 | H28: 2.4m Hood | I28: 6430 | J28: 6450 | O28: 1st | P28: Center | Q28: =SUM(COUNTIF(F28,"Occupied"),Countif(F28,"Churning"),Countif(F28,"Sold"),COUNTIFS(F28,"Vacant",M28,"<>")) -> 0
A29: SA - RUH - Malga (1) | B29: Hot | C29: A | D29: a1L5G000004NKhtUAG | E29: K16 (Hot) - SA - RUH - Malga 1 | G29: 11.9 | H29: 2.0m | I29: 5148 | J29: 7250 | K29: 6200 | O29: 1st Floor | P29: North West | Q29: =SUM(COUNTIF(F29,"Occupied"),Countif(F29,"Churning"),Countif(F29,"Sold"),COUNTIFS(F29,"Vacant",M29,"<>")) -> 0
A30: SA - RUH - Malga (1) | B30: Hot | C30: C | D30: a1L5G000004NKhvUAG | E30: K18 (Hot) - SA - RUH - Malga 1 | G30: 16.9 | H30: 3.0m | I30: 6437 | J30: 9050 | K30: 7750 | O30: 1st Floor | P30: North West | Q30: =SUM(COUNTIF(F30,"Occupied"),Countif(F30,"Churning"),Countif(F30,"Sold"),COUNTIFS(F30,"Vacant",M30,"<>")) -> 0
A31: SA - RUH - Malga (1) | B31: Hot | C31: C | D31: a1L5G000004NKhwUAG | E31: K19 (Hot) - SA - RUH - Malga 1 | G31: 16 | H31: 2.4m | I31: 6008 | J31: 8450 | K31: 7300 | O31: 1st Floor | P31: North West | Q31: =SUM(COUNTIF(F31,"Occupied"),Countif(F31,"Churning"),Countif(F31,"Sold"),COUNTIFS(F31,"Vacant",M31,"<>")) -> 0
A32: SA - RUH - Malga (1) | B32: Hot | C32: A | D32: a1L5G000004NKhlUAG | E32: K08 (Hot) - SA - RUH - Malga 1 | G32: 11.3 | H32: 2.0m | I32: 5148 | J32: 7250 | K32: 6200 | O32: GF | P32: North West | Q32: =SUM(COUNTIF(F32,"Occupied"),Countif(F32,"Churning"),Countif(F32,"Sold"),COUNTIFS(F32,"Vacant",M32,"<>")) -> 0
A33: SA - QSM - Al Bishr | B33: Hot | C33: E | D33: a1L6T00000d2MvuUAE | E33: K13 (Hot) - SA - RUH - QSM | F33: Churning | G33: 21.06 | H33: 3.0m | I33: 3229 | J33: 2750 | K33: 3900 | L33: 006VO00000TRgP3YAL | M33: Samoli Ep | N33: Riyad Ali | O33: 2nd | Q33: =SUM(COUNTIF(F33,"Occupied"),Countif(F33,"Churning"),Countif(F33,"Sold"),COUNTIFS(F33,"Vacant",M33,"<>")) -> 1
A34: SA - AHS - Hofuf | B34: Hot | C34: B | D34: a1L6T00000iJLZdUAO | E34: K06 (Hot)- KSA - AHS- Hofuf | F34: Churning | G34: 14.78 | H34: 2.4m Hood | I34: 2975.44 | J34: 2400 | K34: 3500 | L34: 006VO00000dcowbYAA | M34: Nukhba al Wasal hofouf | N34: Riyad Ali | O34: GF | Q34: =SUM(COUNTIF(F34,"Occupied"),Countif(F34,"Churning"),Countif(F34,"Sold"),COUNTIFS(F34,"Vacant",M34,"<>")) -> 1
A35: SA - RUH - Khaleej | B35: Hot | C35: A | D35: a1L5G000004NSiDUAW | E35: K26 (Hot) - SA - RUH - Khaleej | F35: Churning | G35: 11.97 | H35: 2.0m | I35: 2482 | J35: 3600 | K35: 3000 | L35: 006VO00000eOAaHYAW | M35: Al Normani Khaleej | N35: Shiraz Ali | O35: 1st | P35: East | Q35: =SUM(COUNTIF(F35,"Occupied"),Countif(F35,"Churning"),Countif(F35,"Sold"),COUNTIFS(F35,"Vacant",M35,"<>")) -> 1
A36: SA - RUH - Olaya | B36: Hot | C36: C | D36: a1L5G000004Tzj8UAC | E36: K16 (Hot) - SA - RUH - Olaya | F36: Churning | G36: 16 | H36: 2.4m | I36: 8592 | J36: 9500 | K36: 10350 | O36: 1st | P36: Center | Q36: =SUM(COUNTIF(F36,"Occupied"),Countif(F36,"Churning"),Countif(F36,"Sold"),COUNTIFS(F36,"Vacant",M36,"<>")) -> 1
A37: SA - RUH - Wadi | B37: Hot | C37: D | D37: a1L5G000004TzoXUAS | E37: K07 (Hot) - SA - RUH - Wadi | F37: Churning | G37: 18.1 | H37: 2.4m | I37: 7096 | J37: 7100 | K37: 8550 | O37: G | P37: North | Q37: =SUM(COUNTIF(F37,"Occupied"),Countif(F37,"Churning"),Countif(F37,"Sold"),COUNTIFS(F37,"Vacant",M37,"<>")) -> 1
A38: SA - RUH - Wadi | B38: Hot | C38: E | D38: a1L5G000004TzpbUAC | E38: K45 (Hot) - SA - RUH - Wadi | F38: Churning | G38: 20.8 | H38: 2.4m | I38: 7514 | J38: 7550 | K38: 9100 | O38: 1st | P38: North | Q38: =SUM(COUNTIF(F38,"Occupied"),Countif(F38,"Churning"),Countif(F38,"Sold"),COUNTIFS(F38,"Vacant",M38,"<>")) -> 1
A39: SA - RUH - Qurtoba | B39: Hot | C39: C | D39: a1L5G000004TzsPUAS | E39: K10 (Hot) SA - RUH - Qurtoba | F39: Churning | G39: 16 | H39: 2.4m | I39: 4799 | J39: 6750 | K39: 5800 | O39: G | P39: North East | Q39: =SUM(COUNTIF(F39,"Occupied"),Countif(F39,"Churning"),Countif(F39,"Sold"),COUNTIFS(F39,"Vacant",M39,"<>")) -> 1
A40: SA - RUH - Dahrat Laban | B40: Hot | C40: B | D40: a1L5G000004TzmgUAC | E40: K16 (Hot) - SA - RUH - Dahrat Laban | F40: Churning | G40: 14.54 | H40: 2.4m | I40: 4666 | J40: 4700 | K40: 5650 | O40: Mez | P40: South West | Q40: =SUM(COUNTIF(F40,"Occupied"),Countif(F40,"Churning"),Countif(F40,"Sold"),COUNTIFS(F40,"Vacant",M40,"<>")) -> 1
A41: SA - RUH - Wadi | B41: Hot | C41: D | D41: a1L5G000004TzoIUAS | E41: K04 (Hot) - SA - RUH - Wadi | F41: Churning | G41: 18.1 | H41: 2.4m | I41: 7096 | J41: 7100 | K41: 8550 | O41: G | P41: North | Q41: =SUM(COUNTIF(F41,"Occupied"),Countif(F41,"Churning"),Countif(F41,"Sold"),COUNTIFS(F41,"Vacant",M41,"<>")) -> 1
A42: SA - DMM - Zuhur | B42: Hot | C42: G | D42: a1L5G000004NecqUAC | E42: K22 (Hot) - SA - DMM - Zuhur | F42: Churning | G42: 24.71 | H42: 4.0m | I42: 4750 | J42: 5700 | K42: 5700 | O42: 1st Floor | Q42: =SUM(COUNTIF(F42,"Occupied"),Countif(F42,"Churning"),Countif(F42,"Sold"),COUNTIFS(F42,"Vacant",M42,"<>")) -> 1
A43: SA - RUH - Khaleej | B43: Hot | C43: D | D43: a1L5G000004NSi3UAG | E43: K16 (Hot) - SA - RUH - Khaleej | F43: Churning | G43: 19.55 | H43: 3.0m | I43: 3944 | J43: 5750 | K43: 4750 | O43: 1st | P43: East | Q43: =SUM(COUNTIF(F43,"Occupied"),Countif(F43,"Churning"),Countif(F43,"Sold"),COUNTIFS(F43,"Vacant",M43,"<>")) -> 1
A44: SA - KBR - Aqrabiya | B44: Hot | C44: C | D44: a1L5G000004NYIEUA4 | E44: K16 (Hot) - SA - KBR - Aqrabiya | F44: Churning | G44: 15.43 | H44: 2.4m | I44: 4250 | J44: 4900 | K44: 5100 | O44: 1st Floor | Q44: =SUM(COUNTIF(F44,"Occupied"),Countif(F44,"Churning"),Countif(F44,"Sold"),COUNTIFS(F44,"Vacant",M44,"<>")) -> 1
A45: SA - KBR - Aqrabiya | B45: Hot | C45: C | D45: a1L5G000004NYIDUA4 | E45: K15 (Hot) - SA - KBR - Aqrabiya | F45: Churning | G45: 15.67 | H45: 2.4m | I45: 4250 | J45: 4900 | K45: 5100 | O45: 1st Floor | Q45: =SUM(COUNTIF(F45,"Occupied"),Countif(F45,"Churning"),Countif(F45,"Sold"),COUNTIFS(F45,"Vacant",M45,"<>")) -> 1
A46: SA - KBR - Aqrabiya | B46: Hot | C46: D | D46: a1L5G000004NYI4UAO | E46: K06 (Hot) - SA - KBR - Aqrabiya | F46: Churning | G46: 18.31 | H46: 3.0m | I46: 4990 | J46: 5750 | K46: 6000 | O46: GF | Q46: =SUM(COUNTIF(F46,"Occupied"),Countif(F46,"Churning"),Countif(F46,"Sold"),COUNTIFS(F46,"Vacant",M46,"<>")) -> 1
A47: SA - RUH - Qurtoba | B47: Hot | C47: C | D47: a1L5G000004TzstUAC | E47: K18 (Hot) SA - RUH - Qurtoba | F47: Churning | G47: 16 | H47: 2.4m | I47: 4799 | J47: 6750 | K47: 5800 | O47: G | P47: North East | Q47: =SUM(COUNTIF(F47,"Occupied"),Countif(F47,"Churning"),Countif(F47,"Sold"),COUNTIFS(F47,"Vacant",M47,"<>")) -> 1
A48: SA - RUH - Qurtoba | B48: Hot | C48: F | D48: a1L5G000004TzsoUAC | E48: K16 (Hot) SA - RUH - Qurtoba | F48: Churning | G48: 22 | H48: 2.4m | I48: 6090 | J48: 8550 | K48: 7350 | O48: G | P48: North East | Q48: =SUM(COUNTIF(F48,"Occupied"),Countif(F48,"Churning"),Countif(F48,"Sold"),COUNTIFS(F48,"Vacant",M48,"<>")) -> 1
A49: SA - RUH - Qurtoba | B49: Hot | C49: F | D49: a1L5G000004TzsjUAC | E49: K15 (Hot) SA - RUH - Qurtoba | F49: Churning | G49: 22 | H49: 2.4m | I49: 6090 | J49: 8550 | K49: 7350 | O49: G | P49: North East | Q49: =SUM(COUNTIF(F49,"Occupied"),Countif(F49,"Churning"),Countif(F49,"Sold"),COUNTIFS(F49,"Vacant",M49,"<>")) -> 1
A50: SA - RUH - Qurtoba | B50: Hot | C50: D | D50: a1L5G000004TztDUAS | E50: K22 (Hot) SA - RUH - Qurtoba | F50: Churning | G50: 17 | H50: 2.4m | I50: 5731 | J50: 8050 | K50: 6900 | O50: G | P50: North East | Q50: =SUM(COUNTIF(F50,"Occupied"),Countif(F50,"Churning"),Countif(F50,"Sold"),COUNTIFS(F50,"Vacant",M50,"<>")) -> 1
A51: SA - RUH - Qurtoba | B51: Cold | C51: Cold | D51: a1L5G000004TzuuUAC | E51: K02 (Cold) SA - RUH - Qurtoba | F51: Churning | G51: 11 | H51: Cold | I51: 3580 | J51: 5050 | K51: 4350 | O51: G | P51: North East | Q51: =SUM(COUNTIF(F51,"Occupied"),Countif(F51,"Churning"),Countif(F51,"Sold"),COUNTIFS(F51,"Vacant",M51,"<>")) -> 1
...

Sheet SF Churn Data
A1: Account Name | B1: Type | C1: Category | D1: Kitchen Number ID 18 | E1: Kitchen Number Name | F1: Status | G1: Kitchen Size (Sq. Meters) | H1: Hood Size | I1: Floor Price | J1: MSRP | K1: Activation Fee | L1: Opportunity ID 18 | M1: Opportunity Name | N1: Opportunity Owner: Full Name | O1: Floor | P1: Electric Load (kW) | Q1: Gas Load (kW) | R1: Churn Date
A2: SA - RUH - Malga (2) | B2: Hot | C2: B | D2: a1L5G000004OE0LUAW | E2: K09 (Hot) - SA - RUH - Malga 2 | F2: Churning | G2: 11.75 | H2: 2.4m | I2: 4684 | J2: 4850 | K2: 5650 | L2: 006VO00000ZCdO1YAL | M2: Shawaya House, Malga2 - Churn Transfer | N2: Mohammad Khair Bezzi | O2: GF | P2: 40 Amps | Q2: 37 mBar | R2: 46064
A3: SA - AHS - Hofuf | B3: Hot | C3: B | D3: a1L6T00000iJLZdUAO | E3: K06 (Hot)- KSA - AHS- Hofuf | F3: Churning | G3: 14.78 | H3: 2.4m Hood | I3: 2975.44 | J3: 3100 | K3: 3500 | L3: 006VO00000ZmYb7YAF | M3: La Creperie - Member Transfer - Member Transfer | N3: Riyad Ali | O3: GF | P3: 40 Amps | Q3: 37 mBar | R3: 46065
A4: SA - RUH - Yasmin | B4: Cold | C4: Cold | D4: a1L6T00000iJdvcUAC | E4: K10 (Cold) - SA - RUH - Yasmin | F4: Churning | G4: 12.04 | H4: Cold | I4: 3900 | J4: 4050 | L4: 006VO000003UM4bYAG | M4: Fudge & Co | N4: Osama Eliewa | O4: 1st | R4: 46068
A5: SA - RUH - Qurtoba | B5: Hot | C5: F | D5: a1L5G000004TzsoUAC | E5: K16 (Hot) SA - RUH - Qurtoba | F5: Churning | G5: 22 | H5: 2.4m | I5: 6090 | J5: 6300 | K5: 7350 | L5: 006VO000009CLQDYA4 | M5: Taj Holding - (QUR) | N5: Yousif Almohammedali | O5: G | P5: 40 Amps | Q5: 37 mBar | R5: 46068
A6: SA - RUH - Qurtoba | B6: Hot | C6: C | D6: a1L5G000004TzsPUAS | E6: K10 (Hot) SA - RUH - Qurtoba | F6: Churning | G6: 16 | H6: 2.4m | I6: 4799 | J6: 4950 | K6: 5800 | L6: 006VO00000ZOfttYAD | M6: Asrar Basitah Company (Asrar Al Chef - Chef Secrets) | N6: Mohammad Khair Bezzi | O6: G | P6: 40 Amps | Q6: 37 mBar | R6: 46068
A7: SA - RUH - Yasmin | B7: Hot | C7: D | D7: a1L6T00000iJdvVUAS | E7: K03 (Hot) - SA - RUH - Yasmin | F7: Churning | G7: 18.84 | H7: 3.0m | I7: 6200 | J7: 6400 | L7: 006VO00000UVN5VYAX | M7: Romeno, Yasmin | N7: Mohammad Khair Bezzi | O7: 1st | R7: 46073
A8: SA - QSM - Al Bishr | B8: Hot | C8: E | D8: a1L6T00000d2MvuUAE | E8: K13 (Hot) - SA - RUH - QSM | F8: Churning | G8: 21.06 | H8: 3.0m | I8: 3229 | J8: 3350 | K8: 3900 | L8: 006VO00000HIKMfYAP | M8: Subway - Sharidah Group | N8: Shiraz Ali | O8: 2nd | P8: 40 Amps | Q8: 37 mBar | R8: 46078
A9: SA - KBR - Aqrabiya | B9: Hot | C9: C | D9: a1L5G000004NYIDUA4 | E9: K15 (Hot) - SA - KBR - Aqrabiya | F9: Churning | G9: 15.67 | H9: 2.4m | I9: 4250 | J9: 4400 | K9: 5100 | L9: 006VO00000AqxkdYAB | M9: Deboned (KBR) - Delayed Transfer | N9: Yousif Almohammedali | O9: 1st Floor | P9: 40 Amps | Q9: 37 mBar | R9: 46081
A10: SA - KBR - Aqrabiya | B10: Hot | C10: C | D10: a1L5G000004NYIEUA4 | E10: K16 (Hot) - SA - KBR - Aqrabiya | F10: Churning | G10: 15.43 | H10: 2.4m | I10: 4250 | J10: 4400 | K10: 5100 | L10: 006VO00000Ar4FpYAJ | M10: Deboned KSA (KBR) - Delayed Transfer | N10: Yousif Almohammedali | O10: 1st Floor | P10: 40 Amps | Q10: 37 mBar | R10: 46081
A11: SA - DMM - Zuhur | B11: Hot | C11: G | D11: a1L5G000004NecqUAC | E11: K22 (Hot) - SA - DMM - Zuhur | F11: Churning | G11: 24.71 | H11: 4.0m | I11: 4750 | J11: 4900 | K11: 5700 | L11: 006VO00000GJYzFYAX | M11: Deboned.KSA (Zuhur) - Delayed Transfer - Member Transfer | N11: Yousif Almohammedali | O11: 1st Floor | P11: 40 Amps | Q11: 37 mBar | R11: 46081
A12: SA - RUH - Malga (2) | B12: Hot | C12: C | D12: a1L5G000004OE0RUAW | E12: K19 (Hot) - SA - RUH - Malga 2 | F12: Churning | G12: 15.6 | H12: 3.0m | I12: 5494 | J12: 5700 | K12: 6600 | L12: 006VO00000Tz6EIYAZ | M12: KSTRD | N12: Mussad Al-battah | O12: 1st | P12: 40 Amps | Q12: 37 mBar | R12: 46081
A13: SA - RUH - Arid (2) | B13: Hot | C13: B | D13: a1LVO000004E9Nh2AK | E13: K05 (Hot) - SA - RUH - Arid (2) | F13: Churning | G13: 14.04 | H13: 2.4m | I13: 6000 | L13: 006VO00000WCoTFYA1 | M13: Oregano Pizzeria Sweidi - Member Transfer - Member Transfer | N13: Shiraz Ali | O13: GF | R13: 46081
A14: SA - RUH - Wadi | B14: Hot | C14: D | D14: a1L5G000004TzoXUAS | E14: K07 (Hot) - SA - RUH - Wadi | F14: Churning | G14: 18.1 | H14: 2.4m | I14: 7096 | J14: 7350 | K14: 8550 | L14: 006VO00000ZSmlWYAT | M14: Jofenate - Dawood Ismail Start Up - Churn Transfer | N14: Yousif Almohammedali | O14: G | P14: 40 Amps | Q14: 37 mBar | R14: 46081
A15: SA - RUH - Wadi | B15: Hot | C15: E | D15: a1L5G000004TzpbUAC | E15: K45 (Hot) - SA - RUH - Wadi | F15: Churning | G15: 20.8 | H15: 2.4m | I15: 7514 | J15: 7750 | K15: 9100 | L15: 0065G00000aFhMaQAK | M15: Elfeshawy Restaurant | N15: Osama Eliewa | O15: 1st | P15: 40 Amps | Q15: 37 mBar | R15: 46082
A16: SA - RUH - Qurtoba | B16: Hot | C16: D | D16: a1L5G000004TztDUAS | E16: K22 (Hot) SA - RUH - Qurtoba | F16: Churning | G16: 17 | H16: 2.4m | I16: 5731 | J16: 5950 | K16: 6900 | L16: 006VO00000PK6UJYA1 | M16: Brisket SA - Member Transfer - Member Transfer | N16: Ihab Ghoussainy | O16: G | P16: 40 Amps | Q16: 37 mBar | R16: 46082
A17: SA - RUH - Wadi | B17: Hot | C17: D | D17: a1L5G000004TzoIUAS | E17: K04 (Hot) - SA - RUH - Wadi | F17: Churning | G17: 18.1 | H17: 2.4m | I17: 7096 | J17: 7350 | K17: 8550 | L17: 006VO00000SljHjYAJ | M17: Cassaro | N17: Shiraz Ali | O17: G | P17: 40 Amps | Q17: 37 mBar | R17: 46082
A18: SA - RUH - Malga (1) | B18: Cold | C18: Cold | D18: a1L5G000004NKhmUAG | E18: K09 (Cold) - SA - RUH - Malga 1 | F18: Churning | G18: 10.4 | H18: Cold | I18: 3257 | J18: 3400 | K18: 4000 | L18: 006VO00000Szll3YAB | M18: Planet Donuts KSA | N18: Ahmad El-Basst | O18: 2nd Floor | P18: 30 Amps | Q18: N/A | R18: 46082
A19: SA - RUH - Qurtoba | B19: Cold | C19: Cold | D19: a1L5G000004TzuuUAC | E19: K02 (Cold) SA - RUH - Qurtoba | F19: Churning | G19: 11 | H19: Cold | I19: 3580 | J19: 3700 | K19: 4350 | L19: 006VO00000VnZvtYAF | M19: Planet Donuts KSA | N19: Ahmad El-Basst | O19: G | P19: 30 Amps | Q19: N/A | R19: 46082
A20: SA - RUH - Olaya | B20: Hot | C20: C | D20: a1L5G000004Tzj8UAC | E20: K16 (Hot) - SA - RUH - Olaya | F20: Churning | G20: 16 | H20: 2.4m | I20: 8592 | J20: 8850 | K20: 10350 | L20: 006VO00000XAZEPYA5 | M20: Farmeez Bakery & Sweet - Flavors & More, Olaya | N20: Mohammad Khair Bezzi | O20: 1st | P20: 40 Amps | Q20: 37 mBar | R20: 46082
A21: SA - RUH - Khaleej | B21: Hot | C21: D | D21: a1L5G000004NSi3UAG | E21: K16 (Hot) - SA - RUH - Khaleej | F21: Churning | G21: 19.55 | H21: 3.0m | I21: 3944 | J21: 4100 | K21: 4750 | L21: 006VO00000XAa2PYAT | M21: Farmeez Bakery & Sweet - Flavors & More, Khaleej | N21: Mohammad Khair Bezzi | O21: 1st | P21: 40 Amps | Q21: 37 mBar | R21: 46082
A22: SA - RUH - Dahrat Laban | B22: Hot | C22: B | D22: a1L5G000004TzmgUAC | E22: K16 (Hot) - SA - RUH - Dahrat Laban | F22: Churning | G22: 14.54 | H22: 2.4m | I22: 4666 | J22: 4850 | K22: 5650 | L22: 006VO00000bVrHGYA0 | M22: Kabab hub - Member Transfer | N22: Ahmad El-Basst | O22: Mez | P22: 40 Amps | Q22: 37 mBar | R22: 46082
A23: SA - RUH - Qurtoba | B23: Hot | C23: C | D23: a1L5G000004TzstUAC | E23: K18 (Hot) SA - RUH - Qurtoba | F23: Churning | G23: 16 | H23: 2.4m | I23: 4799 | J23: 4950 | K23: 5800 | L23: 006VO00000bVsZtYAK | M23: Roma company Kebab hub - Well done - Member Transfer | N23: Ahmad El-Basst | O23: G | P23: 40 Amps | Q23: 37 mBar | R23: 46082
A24: SA - RUH - Khaleej | B24: Hot | C24: A | D24: a1L5G000004NSiDUAW | E24: K26 (Hot) - SA - RUH - Khaleej | F24: Churning | G24: 11.97 | H24: 2.0m | I24: 2482 | J24: 2600 | K24: 3000 | L24: 006VO00000bb4x1YAA | M24: Planet Donuts KSA - Member Transfer | N24: Ahmad El-Basst | O24: 1st | P24: 40 Amps | Q24: 37 mBar | R24: 46082
A25: SA - DMM - Rawda | B25: Hot | C25: C | D25: a1L6T00000iJ1ELUA0 | E25: K12 (Hot) - SA - DMM - Rawda | F25: Churning | G25: 15.44 | H25: 2.4m | I25: 3150 | J25: 3250 | K25: 3700 | L25: 006VO00000LKloIYAT | M25: AlYasmen Company - Churn Transfer | N25: Mussad Al-battah | O25: 1st | P25: 40 Amps | Q25: 37 mBar | R25: 46085
... A35: SA - DMM - Rawda | B35: Hot | C35: F | D35: a1L6T00000iJ1EPUA0 | E35: K06 (Hot) - SA - DMM - Rawda | F35: Churning | G35: 22.69 | H35: 4.0m | I35: 4150 | J35: 4300 | K35: 4800 | L35: 006VO000007SnY1YAK | M35: TAKE | N35: Yousif Almohammedali | O35: GF | P35: 40 Amps | Q35: 37 mBar | R35: 46142

Sheet KSA Facility details
A1: =IFERROR(__xludf.DUMMYFUNCTION("IMPORTRANGE(""https://docs.google.com/spreadsheets/d/13fYxFebXtxNn_D_3MCocKQ0TNDUGI3oe20PQCwwHVIY/edit#gid=0"",""Saudi!A:Y"")"),"No.") -> No. | B1: =IFERROR(__xludf.DUMMYFUNCTION("""COMPUTED_VALUE"""),"Facility Code") -> Facility Code | C1: =IFERROR(__xludf.DUMMYFUNCTION("""COMPUTED_VALUE"""),"UR sheet") -> UR sheet | D1: =IFERROR(__xludf.DUMMYFUNCTION("""COMPUTED_VALUE"""),"Facility name") -> Facility name | E1: =IFERROR(__xludf.DUMMYFUNCTION("""COMPUTED_VALUE"""),"Kitchens") -> Kitchens | F1: =IFERROR(__xludf.DUMMYFUNCTION("""COMPUTED_VALUE"""),"Partial Go Live Date") -> Partial Go Live Date | G1: =IFERROR(__xludf.DUMMYFUNCTION("""COMPUTED_VALUE"""),"Full Go Live Date") -> Full Go Live Date | H1: =IFERROR(__xludf.DUMMYFUNCTION("""COMPUTED_VALUE"""),"Status") -> Status | I1: =IFERROR(__xludf.DUMMYFUNCTION("""COMPUTED_VALUE"""),"Location") -> Location | J1: =IFERROR(__xludf.DUMMYFUNCTION("""COMPUTED_VALUE"""),"Layout") -> Layout | K1: =IFERROR(__xludf.DUMMYFUNCTION("""COMPUTED_VALUE"""),"LODs") -> LODs | L1: =IFERROR(__xludf.DUMMYFUNCTION("""COMPUTED_VALUE"""),"SF Update") -> SF Update | M1: =IFERROR(__xludf.DUMMYFUNCTION("""COMPUTED_VALUE"""),"Retail Space") -> Retail Space | N1: =IFERROR(__xludf.DUMMYFUNCTION("""COMPUTED_VALUE"""),"Address") -> Address
A2: =IFERROR(__xludf.DUMMYFUNCTION("""COMPUTED_VALUE"""),1.0) -> 1 | B2: =IFERROR(__xludf.DUMMYFUNCTION("""COMPUTED_VALUE"""),"SA - RUH - Qurtoba") -> SA - RUH - Qurtoba | C2: =IFERROR(__xludf.DUMMYFUNCTION("""COMPUTED_VALUE"""),"Link") -> Link | D2: =IFERROR(__xludf.DUMMYFUNCTION("""COMPUTED_VALUE"""),"Qurtoba") -> Qurtoba | E2: =IFERROR(__xludf.DUMMYFUNCTION("""COMPUTED_VALUE"""),52.0) -> 52 | F2: =IFERROR(__xludf.DUMMYFUNCTION("""COMPUTED_VALUE"""),"-") -> - | G2: =IFERROR(__xludf.DUMMYFUNCTION("""COMPUTED_VALUE"""),44090.0) -> 44090 | H2: =IFERROR(__xludf.DUMMYFUNCTION("""COMPUTED_VALUE"""),"Live") -> Live | I2: =IFERROR(__xludf.DUMMYFUNCTION("""COMPUTED_VALUE"""),"Link") -> Link | J2: =IFERROR(__xludf.DUMMYFUNCTION("""COMPUTED_VALUE"""),"Link") -> Link | K2: =IFERROR(__xludf.DUMMYFUNCTION("""COMPUTED_VALUE"""),"Link") -> Link | L2: =IFERROR(__xludf.DUMMYFUNCTION("""COMPUTED_VALUE"""),TRUE) -> TRUE | M2: =IFERROR(__xludf.DUMMYFUNCTION("""COMPUTED_VALUE"""),FALSE) -> FALSE | N2: =IFERROR(__xludf.DUMMYFUNCTION("""COMPUTED_VALUE"""),"RPCJ+54 Qurtubah, Riyadh Saudi Arabia") -> RPCJ+54 Qurtubah, Riyadh Saudi Arabia
A3: =IFERROR(__xludf.DUMMYFUNCTION("""COMPUTED_VALUE"""),2.0) -> 2 | B3: =IFERROR(__xludf.DUMMYFUNCTION("""COMPUTED_VALUE"""),"SA - RUH - Wadi") -> SA - RUH - Wadi | C3: =IFERROR(__xludf.DUMMYFUNCTION("""COMPUTED_VALUE"""),"Link") -> Link | D3: =IFERROR(__xludf.DUMMYFUNCTION("""COMPUTED_VALUE"""),"Wadi") -> Wadi | E3: =IFERROR(__xludf.DUMMYFUNCTION("""COMPUTED_VALUE"""),56.0) -> 56 | F3: =IFERROR(__xludf.DUMMYFUNCTION("""COMPUTED_VALUE"""),"-") -> - | G3: =IFERROR(__xludf.DUMMYFUNCTION("""COMPUTED_VALUE"""),44130.0) -> 44130 | H3: =IFERROR(__xludf.DUMMYFUNCTION("""COMPUTED_VALUE"""),"Live") -> Live | I3: =IFERROR(__xludf.DUMMYFUNCTION("""COMPUTED_VALUE"""),"Link") -> Link | J3: =IFERROR(__xludf.DUMMYFUNCTION("""COMPUTED_VALUE"""),"Link") -> Link | K3: =IFERROR(__xludf.DUMMYFUNCTION("""COMPUTED_VALUE"""),"Link") -> Link | L3: =IFERROR(__xludf.DUMMYFUNCTION("""COMPUTED_VALUE"""),TRUE) -> TRUE | M3: =IFERROR(__xludf.DUMMYFUNCTION("""COMPUTED_VALUE"""),FALSE) -> FALSE | N3: =IFERROR(__xludf.DUMMYFUNCTION("""COMPUTED_VALUE"""),"QMPJ+XR Al Wadi, Riyadh Saudi Arabia") -> QMPJ+XR Al Wadi, Riyadh Saudi Arabia
A4: =IFERROR(__xludf.DUMMYFUNCTION("""COMPUTED_VALUE"""),3.0) -> 3 | B4: =IFERROR(__xludf.DUMMYFUNCTION("""COMPUTED_VALUE"""),"SA - RUH - Olaya") -> SA - RUH - Olaya | C4: =IFERROR(__xludf.DUMMYFUNCTION("""COMPUTED_VALUE"""),"Link") -> Link | D4: =IFERROR(__xludf.DUMMYFUNCTION("""COMPUTED_VALUE"""),"Olaya") -> Olaya | E4: =IFERROR(__xludf.DUMMYFUNCTION("""COMPUTED_VALUE"""),22.0) -> 22 | F4: =IFERROR(__xludf.DUMMYFUNCTION("""COMPUTED_VALUE"""),"-") -> - | G4: =IFERROR(__xludf.DUMMYFUNCTION("""COMPUTED_VALUE"""),44168.0) -> 44168 | H4: =IFERROR(__xludf.DUMMYFUNCTION("""COMPUTED_VALUE"""),"Live") -> Live | I4: =IFERROR(__xludf.DUMMYFUNCTION("""COMPUTED_VALUE"""),"Link") -> Link | J4: =IFERROR(__xludf.DUMMYFUNCTION("""COMPUTED_VALUE"""),"Link") -> Link | K4: =IFERROR(__xludf.DUMMYFUNCTION("""COMPUTED_VALUE"""),"Link") -> Link | L4: =IFERROR(__xludf.DUMMYFUNCTION("""COMPUTED_VALUE"""),TRUE) -> TRUE | M4: =IFERROR(__xludf.DUMMYFUNCTION("""COMPUTED_VALUE"""),FALSE) -> FALSE | N4: =IFERROR(__xludf.DUMMYFUNCTION("""COMPUTED_VALUE"""),"MMVW+54 Al Olaya, Riyadh Saudi Arabia") -> MMVW+54 Al Olaya, Riyadh Saudi Arabia
A5: =IFERROR(__xludf.DUMMYFUNCTION("""COMPUTED_VALUE"""),4.0) -> 4 | B5: =IFERROR(__xludf.DUMMYFUNCTION("""COMPUTED_VALUE"""),"SA - RUH - Dahrat Laban") -> SA - RUH - Dahrat Laban | C5: =IFERROR(__xludf.DUMMYFUNCTION("""COMPUTED_VALUE"""),"Link") -> Link | D5: =IFERROR(__xludf.DUMMYFUNCTION("""COMPUTED_VALUE"""),"Dahrat Laban") -> Dahrat Laban | E5: =IFERROR(__xludf.DUMMYFUNCTION("""COMPUTED_VALUE"""),38.0) -> 38 | F5: =IFERROR(__xludf.DUMMYFUNCTION("""COMPUTED_VALUE"""),"-") -> - | G5: =IFERROR(__xludf.DUMMYFUNCTION("""COMPUTED_VALUE"""),44270.0) -> 44270 | H5: =IFERROR(__xludf.DUMMYFUNCTION("""COMPUTED_VALUE"""),"Live") -> Live | I5: =IFERROR(__xludf.DUMMYFUNCTION("""COMPUTED_VALUE"""),"Link") -> Link | J5: =IFERROR(__xludf.DUMMYFUNCTION("""COMPUTED_VALUE"""),"Link") -> Link | K5: =IFERROR(__xludf.DUMMYFUNCTION("""COMPUTED_VALUE"""),"Link") -> Link | L5: =IFERROR(__xludf.DUMMYFUNCTION("""COMPUTED_VALUE"""),TRUE) -> TRUE | M5: =IFERROR(__xludf.DUMMYFUNCTION("""COMPUTED_VALUE"""),FALSE) -> FALSE | N5: =IFERROR(__xludf.DUMMYFUNCTION("""COMPUTED_VALUE"""),"3160-3062 Taif Street, Dhahrat Laban, Riyadh 12553, Saudi Arabia") -> 3160-3062 Taif Street, Dhahrat Laban, Riyadh 12553, Saudi Arabia
A6: =IFERROR(__xludf.DUMMYFUNCTION("""COMPUTED_VALUE"""),5.0) -> 5 | B6: =IFERROR(__xludf.DUMMYFUNCTION("""COMPUTED_VALUE"""),"SA - RUH - Sweidi") -> SA - RUH - Sweidi | C6: =IFERROR(__xludf.DUMMYFUNCTION("""COMPUTED_VALUE"""),"Link") -> Link | D6: =IFERROR(__xludf.DUMMYFUNCTION("""COMPUTED_VALUE"""),"Suwaidi") -> Suwaidi | E6: =IFERROR(__xludf.DUMMYFUNCTION("""COMPUTED_VALUE"""),25.0) -> 25 | F6: =IFERROR(__xludf.DUMMYFUNCTION("""COMPUTED_VALUE"""),"-") -> - | G6: =IFERROR(__xludf.DUMMYFUNCTION("""COMPUTED_VALUE"""),44356.0) -> 44356 | H6: =IFERROR(__xludf.DUMMYFUNCTION("""COMPUTED_VALUE"""),"Live") -> Live | I6: =IFERROR(__xludf.DUMMYFUNCTION("""COMPUTED_VALUE"""),"Link") -> Link | J6: =IFERROR(__xludf.DUMMYFUNCTION("""COMPUTED_VALUE"""),"Link") -> Link | K6: =IFERROR(__xludf.DUMMYFUNCTION("""COMPUTED_VALUE"""),"Link") -> Link | L6: =IFERROR(__xludf.DUMMYFUNCTION("""COMPUTED_VALUE"""),TRUE) -> TRUE | M6: =IFERROR(__xludf.DUMMYFUNCTION("""COMPUTED_VALUE"""),FALSE) -> FALSE | N6: =IFERROR(__xludf.DUMMYFUNCTION("""COMPUTED_VALUE"""),"HMQC+J4H, As Suwaidi, Riyadh 12787, Saudi Arabia") -> HMQC+J4H, As Suwaidi, Riyadh 12787, Saudi Arabia
A7: =IFERROR(__xludf.DUMMYFUNCTION("""COMPUTED_VALUE"""),6.0) -> 6 | B7: =IFERROR(__xludf.DUMMYFUNCTION("""COMPUTED_VALUE"""),"SA - RUH - Malga (1)") -> SA - RUH - Malga (1) | C7: =IFERROR(__xludf.DUMMYFUNCTION("""COMPUTED_VALUE"""),"Link") -> Link | D7: =IFERROR(__xludf.DUMMYFUNCTION("""COMPUTED_VALUE"""),"Malga") -> Malga | E7: =IFERROR(__xludf.DUMMYFUNCTION("""COMPUTED_VALUE"""),21.0) -> 21 | F7: =IFERROR(__xludf.DUMMYFUNCTION("""COMPUTED_VALUE"""),"-") -> - | G7: =IFERROR(__xludf.DUMMYFUNCTION("""COMPUTED_VALUE"""),44642.0) -> 44642 | H7: =IFERROR(__xludf.DUMMYFUNCTION("""COMPUTED_VALUE"""),"Live") -> Live | I7: =IFERROR(__xludf.DUMMYFUNCTION("""COMPUTED_VALUE"""),"Link") -> Link | J7: =IFERROR(__xludf.DUMMYFUNCTION("""COMPUTED_VALUE"""),"Link") -> Link | K7: =IFERROR(__xludf.DUMMYFUNCTION("""COMPUTED_VALUE"""),"Link") -> Link | L7: =IFERROR(__xludf.DUMMYFUNCTION("""COMPUTED_VALUE"""),TRUE) -> TRUE | M7: =IFERROR(__xludf.DUMMYFUNCTION("""COMPUTED_VALUE"""),FALSE) -> FALSE | N7: =IFERROR(__xludf.DUMMYFUNCTION("""COMPUTED_VALUE"""),"4050 Nawar Valley, حي الملقا، Riyadh 13521 7813, Saudi Arabia") -> 4050 Nawar Valley, حي الملقا، Riyadh 13521 7813, Saudi Arabia
A8: =IFERROR(__xludf.DUMMYFUNCTION("""COMPUTED_VALUE"""),7.0) -> 7 | B8: =IFERROR(__xludf.DUMMYFUNCTION("""COMPUTED_VALUE"""),"SA - RUH - Khaleej") -> SA - RUH - Khaleej | C8: =IFERROR(__xludf.DUMMYFUNCTION("""COMPUTED_VALUE"""),"Link") -> Link | D8: =IFERROR(__xludf.DUMMYFUNCTION("""COMPUTED_VALUE"""),"Khaleej") -> Khaleej | E8: =IFERROR(__xludf.DUMMYFUNCTION("""COMPUTED_VALUE"""),35.0) -> 35 | F8: =IFERROR(__xludf.DUMMYFUNCTION("""COMPUTED_VALUE"""),"-") -> - | G8: =IFERROR(__xludf.DUMMYFUNCTION("""COMPUTED_VALUE"""),44805.0) -> 44805 | H8: =IFERROR(__xludf.DUMMYFUNCTION("""COMPUTED_VALUE"""),"Live") -> Live | I8: =IFERROR(__xludf.DUMMYFUNCTION("""COMPUTED_VALUE"""),"Link") -> Link | J8: =IFERROR(__xludf.DUMMYFUNCTION("""COMPUTED_VALUE"""),"Link") -> Link | K8: =IFERROR(__xludf.DUMMYFUNCTION("""COMPUTED_VALUE"""),"Link") -> Link | L8: =IFERROR(__xludf.DUMMYFUNCTION("""COMPUTED_VALUE"""),TRUE) -> TRUE | M8: =IFERROR(__xludf.DUMMYFUNCTION("""COMPUTED_VALUE"""),FALSE) -> FALSE | N8: =IFERROR(__xludf.DUMMYFUNCTION("""COMPUTED_VALUE"""),"RFKD3260, 3260 Shaikh Abdulaziz Ibn Abdulrahman Ibn Bishr, 8177، حي الخليج، Riyadh 13223, Saudi Arabia") -> RFKD3260, 3260 Shaikh Abdulaziz Ibn Abdulrahman Ibn Bishr, 8177، حي الخليج، Riyadh 13223, Saudi Arabia
A9: =IFERROR(__xludf.DUMMYFUNCTION("""COMPUTED_VALUE"""),8.0) -> 8 | B9: =IFERROR(__xludf.DUMMYFUNCTION("""COMPUTED_VALUE"""),"SA - KBR - Aqrabiya") -> SA - KBR - Aqrabiya | C9: =IFERROR(__xludf.DUMMYFUNCTION("""COMPUTED_VALUE"""),"Link") -> Link | D9: =IFERROR(__xludf.DUMMYFUNCTION("""COMPUTED_VALUE"""),"Aqrabiya") -> Aqrabiya | E9: =IFERROR(__xludf.DUMMYFUNCTION("""COMPUTED_VALUE"""),30.0) -> 30 | F9: =IFERROR(__xludf.DUMMYFUNCTION("""COMPUTED_VALUE"""),"-") -> - | G9: =IFERROR(__xludf.DUMMYFUNCTION("""COMPUTED_VALUE"""),44788.0) -> 44788 | H9: =IFERROR(__xludf.DUMMYFUNCTION("""COMPUTED_VALUE"""),"Live") -> Live | I9: =IFERROR(__xludf.DUMMYFUNCTION("""COMPUTED_VALUE"""),"Link") -> Link | J9: =IFERROR(__xludf.DUMMYFUNCTION("""COMPUTED_VALUE"""),"Link") -> Link | K9: =IFERROR(__xludf.DUMMYFUNCTION("""COMPUTED_VALUE"""),"Link") -> Link | L9: =IFERROR(__xludf.DUMMYFUNCTION("""COMPUTED_VALUE"""),TRUE) -> TRUE | M9: =IFERROR(__xludf.DUMMYFUNCTION("""COMPUTED_VALUE"""),FALSE) -> FALSE | N9: =IFERROR(__xludf.DUMMYFUNCTION("""COMPUTED_VALUE"""),"EKJC7086, 7086 Al Abrar, 3473، حي العقربية،, Al Khobar 34446, Saudi Arabia") -> EKJC7086, 7086 Al Abrar, 3473، حي العقربية،, Al Khobar 34446, Saudi Arabia
